Workbook
Name E: [1]Baseline!$D$24:$O$25
Name e_coeff: [1]Baseline!$D$49:$O$50
Name E_Y: [1]Baseline!$Q$24:$Z$25
Name ee_coeff: [1]Baseline!$D$36:$O$39
Name ee_Y: [1]Baseline!$Q$11:$V$14
Name I: 'List of functions'!$C$8:$E$10
Name M: 'List of functions'!$C$4:$E$6
Name n_sectors: [1]Baseline!$B$1
Name new_ee_mix: '[1]Shock 3 - Power supply mix'!$B$5:$B$8
Name p: #REF!
Name V: 'List of functions'!$C$12:$C$14
Name v_coeff: [1]Baseline!$D$44:$O$47
Name X_diag: #REF!
Name Y: [1]Baseline!$Q$6:$Z$17
Name z_coeff: [1]Baseline!$D$31:$O$42

Sheet List of functions
A1: Linear Algebra in Excel: remember CTRL+SHIFT+ENTER! (not necessary in latest Excel versions)
A4: Square matrix | B4: M (3,3) | C4: 2 | D4: 5 | E4: 9
C5: 3 | D5: 4 | E5: 5
C6: 7 | D6: 8 | E6: 2
A8: Identity matrix | B8: I (3,3) | C8: {=_xlfn.MUNIT(3)} -> 1 | D8: 0 | E8: 0
C9: 0 | D9: 1 | E9: 0 | G9: =MUNIT(3)
C10: 0 | D10: 0 | E10: 1 | G10: =MATR.UNIT(3)
A12: Vector | B12: V (3,1) | C12: 4
C13: 9
C14: 3
A17: Function | B17: Plain notation | C17: Result | G17: Notes and function names in Italian and in English (check your version's language)
A19: Matrix sum | B19: M + I | G19: only matrices with same dimensions can be summed
A23: Matrix inverse | B23: inv(M) | G23: only square matrices can be inverted
G24: =MINVERSE(M)
G25: =MATR.INVERSA(M)
A27: Matrix product | B27: MV | G27: matrix multiplication can be done only if first matrix has same columns of the rows of the second matrix
G28: =MMULT(M,V)
G29: =MATR.PRODOTTO(M;V)
A31: Diagonal matrix | B31: diag(V) | G31: to diagonalize, use scalar multiplication between the vector to be diagonalized and the identity matrix
G32: =MUNIT(3)*V
G33: =MATR.UNIT(3)*V
A35: Transposed matrix | B35: M' | G35: rows becomes columns and vice-versa
G36: =TRANSPOSE(M)
G37: =MATR.TRASPOSTA(M)

Sheet How to read an IO matrix
B2: Supplier's perspective | D2: Sector A | E2: Sector B | F2: Sector C | H2: Final Demand
C3: Sector A | D3: ↑↑↑ | E3: Where is sector's A output flowing? | H3: ↑↑↑
C4: Sector B
C5: Sector C
B8: Consumer's perspective | D8: Sector A | E8: Sector B | F8: Sector C | H8: Final Demand
C9: Sector A | E9: What does this sector need for producing its output? | H9: What do final consumers need?
C10: Sector B
C11: Sector C

Sheet Ex. 1
A1: Knowing that we need 0.15 ton of steel and 1 k€ of goods and services to produce 1 car, how much is needed from the whole economy to produce 1000 of them? | L1: exogenous variables
L2: decision endogenous variables
L3: derived endogenous variables
A4: technologies | D4: steel | E4: goods & services | G4: car production
B5: environmental extensions
C6: units | D6: ton | E6: k€ | G6: 100 cars
A7: Symbolic solution
D9: z (2,2) | G9: Y (2,1) | I9: w (2,2) = inv(I-z) | L9: X (2,1) = wY
A10: steel | C10: ton | D10: ton/ton | E10: ton/k€ | G10: ton | I10: ton/ton | J10: ton/k€ | L10: ton
A11: goods & services | C11: k€ | D11: k€/ton | E11: k€/k€ | G11: k€ | I11: k€/ton | J11: k€/k€ | L11: k€
D12: r (1,2)
B13: labour | C13: pp | D13: pp/ton | E13: pp/k€
D15: Z (2.2) = z diag(X)
A16: steel | C16: ton | D16: ton | E16: ton
A17: goods & services | C17: k€ | D17: k€ | E17: k€
D18: R (1,2) = r diag(X)
B19: labour | C19: pp | D19: pp | E19: pp
D20: f (1,2) = ew
B21: labour | C21: pp | D21: pp/ton | E21: pp/k€
D22: F (1,2) = f diag(Y)
B23: labour | C23: pp | D23: pp | E23: pp
A25: Numeric solution
D27: z | G27: Y | I27: w | L27: X
A28: steel | C28: ton | D28: 0.07 | E28: 0.05
A29: goods & services | C29: k€ | D29: 1 | E29: 0.2
D30: e
B31: labour | C31: pp | D31: 10 | E31: 18
A34: 1. Empirical demonstration
D41: t=0 | G41: t=1 | J41: t=2 | M41: t=3 | P41: t=4 | S41: t=5
A42: 1 | D42: I | G42: z | J42: zz | M42: zzz | P42: zzzz | S42: zzzzz | V42: sum
A43: steel | D43: {=_xlfn.MUNIT(2)} -> 1 | E43: 0 | F43: + | G43: {=D28:E29} -> 0.07 | H43: 0.05 | I43: + | J43: {=MMULT(G43:H44,$D$28:$E$29)} -> 0.0549 | K43: 0.0135 | L43: + | M43: {=MMULT(J43:K44,D28:E29)} -> 0.017343 | N43: 0.005445 | O43: + | P43: {=MMULT(M43:N44,D28:E29)} -> 0.00665901 | Q43: 0.00195615 | R43: + | S43: {=MMULT(M43:N44,D28:E29)} -> 0.00665901 | T43: 0.00195615 | U43: = | V43: {=S43:T44+P43:Q44+M43:N44+J43:K44+G43:H44+D43:E44} -> 1.155561 | W43: 0.0728573 | X43: roughly = w
A44: goods & services | D44: 0 | E44: 1 | G44: 1 | H44: 0.2 | J44: 0.27 | K44: 0.09 | M44: 0.1089 | N44: 0.0315 | P44: 0.039123 | Q44: 0.011745 | S44: 0.039123 | T44: 0.011745 | V44: 1.457146 | W44: 1.34499
D46: t=0 | F46: t=1 | H46: t=2 | J46: t=3 | L46: t=4 | N46: t=5
A47: 2 | D47: IY | F47: zY | H47: zzY | J47: zzzY | L47: zzzzY | N47: zzzzzY | P47: Column sum
A48: steel | D48: {=MMULT(_xlfn.MUNIT(2),$G$28:$G$29)} -> #VALUE! | E48: + | F48: {=MMULT($D$28:$E$29,$G$28:$G$29)} -> #VALUE! | G48: + | H48: {=MMULT($D$28:$E$29,MMULT($D$28:$E$29,$G$28:$G$29))} -> #VALUE! | I48: + | J48: {=MMULT($D$28:$E$29,MMULT($D$28:$E$29,MMULT($D$28:$E$29,$G$28:$G$29)))} -> #VALUE! | K48: + | L48: {=MMULT($D$28:$E$29,MMULT($D$28:$E$29,MMULT($D$28:$E$29,MMULT($D$28:$E$29,$G$28:$G$29))))} -> #VALUE! | M48: + | N48: {=MMULT($D$28:$E$29,MMULT($D$28:$E$29,MMULT($D$28:$E$29,MMULT($D$28:$E$29,MMULT($D$28:$E$29,$G$28:$G$29)))))} -> #VALUE! | O48: = | P48: =SUM(D48:N48) -> #VALUE! | Q48: roughly = X
A49: goods & services | D49: #VALUE! | F49: #VALUE! | H49: #VALUE! | J49: #VALUE! | L49: #VALUE! | N49: #VALUE! | P49: =SUM(D49:N49) -> #VALUE!
A52: 2. Compute the total production and the total intermediate consumption of each sector of the economy.
D54: Z | G54: X
A55: steel | C55: ton
A56: goods & services | C56: k€
...

Sheet Ex. 1 bis
A1: Actually, the economy also need workers within the cars production sector. Try to include such sector within the economy and recompute the needed resources to produce 100 cars. | L1: exogenous variables
L2: decision endogenous variables
L3: derived endogenous variables
A4: technologies | D4: steel | E4: goods & services | F4: cars production | H4: final demand
B5: value added & environmental extensions
C6: units | D6: ton | E6: k€ | F6: n. cars
A7: Symbolic solution
D9: z (3,3) | H9: Y (3,1) | J9: w (3,3) = inv(I-z) | N9: X (3,1) = wY
A10: steel | C10: ton | D10: ton/ton | E10: ton/k€ | F10: ton/car | H10: ton | J10: ton/ton | K10: ton/k€ | L10: ton/car | N10: ton
A11: goods & services | C11: k€ | D11: k€/ton | E11: k€/k€ | F11: k€/car | H11: k€ | J11: k€/ton | K11: k€/k€ | L11: k€/car | N11: k€
A12: car production | C12: n. cars | D12: car/ton | E12: car/k€ | F12: car/car | H12: n.cars | J12: car/ton | K12: car/k€ | L12: car/car | N12: n. cars
D13: v (1,3)
B14: wages | C14: k€ | D14: €/ton | E14: €/k€ | F14: €/car
D15: r (1,3)
B16: labour | C16: pp | D16: pp/ton | E16: pp/k€ | F16: pp/car
D18: Z (3,3) = z diag(X)
A19: steel | C19: ton | D19: ton | E19: ton | F19: ton
A20: goods & services | C20: k€ | D20: k€ | E20: k€ | F20: k€
A21: car production | C21: n.cars | D21: car | E21: car | F21: car
D22: R (1,3) = r diag(X)
B23: labour | C23: pp | D23: pp/ton | E23: pp/k€ | F23: pp/car
D24: re (1,3) = rw
B25: labour | C25: pp | D25: pp/ton | E25: pp/k€ | F25: pp/car
D26: Re (1,3) = re diag(Y)
B27: labour | C27: pp | D27: pp/ton | E27: pp/k€ | F27: pp/car
D28: V (1,3) = v diag(X)
B29: wages | C29: k€ | D29: k€ | E29: k€ | F29: k€
D30: p (1,3) = vw
B31: price indices | C31: k€ | D31: k€/ton | E31: k€/k€ | F31: k€/car
A33: Numeric solution
A35: 1. Fill the input-output table. Compute the total production from each sector and the number of needed workers.
D37: z | H37: Y | J37: w = inv(I-z) | N37: X = wY
A38: steel | C38: ton | D38: 0.07 | E38: 0.05 | F38: 0.15 | H38: 0 | J38: {=MINVERSE(_xlfn.MUNIT(3)-D38:F40)} -> 1.1527378 | K38: 0.07204611 | L38: 0.89337176 | N38: {=MMULT(J38:L40,H38:H40)} -> 89.337176
A39: goods & services | C39: k€ | D39: 1 | E39: 0.2 | F39: 10 | H39: 0 | J39: 1.4409222 | K39: 1.3400576 | L39: 13.616715 | N39: 1361.6715
A40: car production | C40: n. cars | D40: 0 | E40: 0 | F40: 0 | H40: 100 | J40: 0 | K40: 0 | L40: 1 | N40: 100
D41: r
B42: labour | C42: pp | D42: 10 | E42: 18 | F42: 15
D43: E | H43: R_tot
B44: labour | C44: pp | D44: {=MMULT(D42:F42,_xlfn.MUNIT(3)*N38:N40)} -> 893.37176 | E44: 24510.086 | F44: 1500 | H44: =SUM(D44:F44) -> 26903.458
D45: e
...

Sheet Ex. 2
A1: Let us consider a Technology-by-Technology Multi-Regional Input-Output Table (MRIO, defined in monetary units for year 2019), with two regions (EU27, Rest of the World), each defined by three technologies (Primary, Industry and Services sectors). It is requested to:
A5: region | E5: EU27 | F5: EU27 | G5: EU27 | H5: RoW | I5: RoW | J5: RoW | L5: EU27 | M5: RoW | S5: EU27 | T5: EU27 | U5: EU27 | V5: RoW | W5: RoW | X5: RoW
B6: technologies | E6: Primary | F6: Industry | G6: Services | H6: Primary | I6: Industry | J6: Services | L6: Final demand | M6: Final demand | S6: Primary | T6: Industry | U6: Services | V6: Primary | W6: Industry | X6: Services
C7: value added & environmental extensions
D8: units | E8: M€ | F8: M€ | G8: M€ | H8: M€ | I8: M€ | J8: M€
A9: Symbolic solution
E10: Z (6,6) | L10: Y (6,2) | O10: Y_tot (6,1) = sum(Y) | Q10: X (6,1) = Z*i(rt,1) + Y*i(rt,1)
A11: EU27 | B11: Primary | D11: M€ | E11: M€ | F11: M€ | G11: M€ | H11: M€ | I11: M€ | J11: M€ | L11: M€ | M11: M€ | O11: M€ | Q11: M€
A12: EU27 | B12: Industry | D12: M€ | E12: M€ | F12: M€ | G12: M€ | H12: M€ | I12: M€ | J12: M€ | L12: M€ | M12: M€ | O12: M€ | Q12: M€
A13: EU27 | B13: Services | D13: M€ | E13: M€ | F13: M€ | G13: M€ | H13: M€ | I13: M€ | J13: M€ | L13: M€ | M13: M€ | O13: M€ | Q13: M€
A14: RoW | B14: Primary | D14: M€ | E14: M€ | F14: M€ | G14: M€ | H14: M€ | I14: M€ | J14: M€ | L14: M€ | M14: M€ | O14: M€ | Q14: M€
A15: RoW | B15: Industry | D15: M€ | E15: M€ | F15: M€ | G15: M€ | H15: M€ | I15: M€ | J15: M€ | L15: M€ | M15: M€ | O15: M€ | Q15: M€
A16: RoW | B16: Services | D16: M€ | E16: M€ | F16: M€ | G16: M€ | H16: M€ | I16: M€ | J16: M€ | L16: M€ | M16: M€ | O16: M€ | Q16: M€
E17: R (2,6) NOTE: sometimes this is a unique matrix, sometimes not. | L17: R_Y (2,2) | Q17: Rtot (2,1) = R + R_Y
B18: v | C18: Value added | D18: M€ | E18: M€ | F18: M€ | G18: M€ | H18: M€ | I18: M€ | J18: M€ | L18: M€ | M18: M€ | Q18: M€
B19: e | C19: CO2 emissions | D19: ton | E19: ton | F19: ton | G19: ton | H19: ton | I19: ton | J19: ton | L19: ton | M19: ton | Q19: ton
E20: z (6,6) = Z inv(diag(X)) | L20: R_e_reg (6,2) = diag(r_e)*Y | S20: w (6,6) = inv(I-z)
A21: EU27 | B21: Primary | D21: M€ | E21: M€/M€ | F21: M€/M€ | G21: M€/M€ | H21: M€/M€ | I21: M€/M€ | J21: M€/M€ | L21: ton | M21: ton | S21: M€/M€ | T21: M€/M€ | U21: M€/M€ | V21: M€/M€ | W21: M€/M€ | X21: M€/M€
A22: EU27 | B22: Industry | D22: M€ | E22: M€/M€ | F22: M€/M€ | G22: M€/M€ | H22: M€/M€ | I22: M€/M€ | J22: M€/M€ | L22: ton | M22: ton | S22: M€/M€ | T22: M€/M€ | U22: M€/M€ | V22: M€/M€ | W22: M€/M€ | X22: M€/M€
A23: EU27 | B23: Services | D23: M€ | E23: M€/M€ | F23: M€/M€ | G23: M€/M€ | H23: M€/M€ | I23: M€/M€ | J23: M€/M€ | L23: ton | M23: ton | S23: M€/M€ | T23: M€/M€ | U23: M€/M€ | V23: M€/M€ | W23: M€/M€ | X23: M€/M€
A24: RoW | B24: Primary | D24: M€ | E24: M€/M€ | F24: M€/M€ | G24: M€/M€ | H24: M€/M€ | I24: M€/M€ | J24: M€/M€ | L24: ton | M24: ton | S24: M€/M€ | T24: M€/M€ | U24: M€/M€ | V24: M€/M€ | W24: M€/M€ | X24: M€/M€
A25: RoW | B25: Industry | D25: M€ | E25: M€/M€ | F25: M€/M€ | G25: M€/M€ | H25: M€/M€ | I25: M€/M€ | J25: M€/M€ | L25: ton | M25: ton | S25: M€/M€ | T25: M€/M€ | U25: M€/M€ | V25: M€/M€ | W25: M€/M€ | X25: M€/M€
A26: RoW | B26: Services | D26: M€ | E26: M€/M€ | F26: M€/M€ | G26: M€/M€ | H26: M€/M€ | I26: M€/M€ | J26: M€/M€ | L26: ton | M26: ton | S26: M€/M€ | T26: M€/M€ | U26: M€/M€ | V26: M€/M€ | W26: M€/M€ | X26: M€/M€
E27: r (2,6) = R inv(diag(X)) | L27: F (1,2) = i(1,rt) F
B28: v | C28: Value added | D28: M€ | E28: M€/M€ | F28: M€/M€ | G28: M€/M€ | H28: M€/M€ | I28: M€/M€ | J28: M€/M€ | L28: ton | M28: ton
B29: e | C29: CO2 emissions | D29: ton | E29: ton/M€ | F29: ton/M€ | G29: ton/M€ | H29: ton/M€ | I29: ton/M€ | J29: ton/M€
E30: p (1,6) = v w | L30: E_reg (1,2) = i(1,rt) E
B31: p | C31: price index | D31: M€ | E31: M€/M€ | F31: M€/M€ | G31: M€/M€ | H31: M€/M€ | I31: M€/M€ | J31: M€/M€ | L31: ton | M31: ton
E32: f (1,6) = e w
B33: f | C33: CO2 emissions | D33: ton | E33: ton/M€ | F33: ton/M€ | G33: ton/M€ | H33: ton/M€ | I33: ton/M€ | J33: ton/M€
E34: F (1,6) = f diag(Y)
B35: f | C35: CO2 emissions | D35: ton | E35: ton | F35: ton | G35: ton | H35: ton | I35: ton | J35: ton
A38: Numeric solution
A40: 1. After calculating technical and environmental coefficients matrices, apply the appropriate Leontief models to determine price indices and CO2 footprints specific to the unit of technology activity (in €/€ and kg/€ respectively). Is the database representing a “balanced” economy?
T42: Check our data: CO2 (Gton)
E43: Z | L43: Y | O43: Y_tot | Q43: X | T43: year: 2019
A44: EU27 | B44: Primary | D44: M€ | E44: 54291.686 | F44: 376989.74 | G44: 38450.703 | H44: 2955.2273 | I44: 39983.233 | J44: 7394.7756 | L44: 232354.18 | M44: 19713.979 | O44: =SUM(L44:M44) -> 252068.15 | Q44: =SUM(E44:J44,L44:M44) -> 772133.52 | V44: World | W44: EU27 | X44: RoW
A45: EU27 | B45: Industry | D45: M€ | E45: 136974.51 | F45: 3910671.1 | G45: 1156573.8 | H45: 37765.577 | I45: 705296.88 | J45: 220729.97 | L45: 4697827.3 | M45: 986934.45 | O45: =SUM(L45:M45) -> 5684761.8 | Q45: =SUM(E45:J45,L45:M45) -> 11852774 | U45: data | V45: =Q52/1000000 -> 33.071125 | W45: =SUM(E52:G52,L52)/1000000 -> 3.4423252 | X45: =V45-W45 -> 29.6288
A46: EU27 | B46: Services | D46: M€ | E46: 144971.12 | F46: 2395932.3 | G46: 5313275.7 | H46: 21620.252 | I46: 129409.79 | J46: 275425.2 | L46: 10180229 | M46: 318899.37 | O46: =SUM(L46:M46) -> 10499128 | Q46: =SUM(E46:J46,L46:M46) -> 18779762 | U46: Our World in Data | V46: 37.04 | W46: 2.9 | X46: =V46-W46 -> 34.14
A47: RoW | B47: Primary | D47: M€ | E47: 13329.935 | F47: 240514.71 | G47: 11527.299 | H47: 757814.04 | I47: 4537018.7 | J47: 549701.76 | L47: 81284.073 | M47: 1960204.5 | O47: =SUM(L47:M47) -> 2041488.5 | Q47: =SUM(E47:J47,L47:M47) -> 8151395
...

Sheet Ex. 3
A1: Apply a numerical shock to the original MRIO table, simulating a scenario in which EU27 is shutting down all imports from RoW, producing the same imported products domestically. Determine the relative changes in World Value added, CO2 emissions (assume direct CO2 emissions of final demand to be constant).
A5: region | E5: EU27 | F5: EU27 | G5: EU27 | H5: RoW | I5: RoW | J5: RoW | L5: EU27 | M5: RoW
B6: technologies | E6: Primary | F6: Industry | G6: Services | H6: Primary | I6: Industry | J6: Services | L6: Final demand | M6: Final demand
C7: value added & environmental extensions
D8: units | E8: M€ | F8: M€ | G8: M€ | H8: M€ | I8: M€ | J8: M€
A9: Symbolic solution
E10: z (6,6) | L10: Y (6,2) | O10: Y_tot (6,1) = sum(Y) | Q10: X (6,1) = inv(I-z)*Y_tot
A11: EU27 | B11: Primary | D11: M€ | E11: M€/M€ | F11: M€/M€ | G11: M€/M€ | H11: M€/M€ | I11: M€/M€ | J11: M€/M€ | L11: M€ | M11: M€ | O11: M€ | Q11: M€
A12: EU27 | B12: Industry | D12: M€ | E12: M€/M€ | F12: M€/M€ | G12: M€/M€ | H12: M€/M€ | I12: M€/M€ | J12: M€/M€ | L12: M€ | M12: M€ | O12: M€ | Q12: M€
A13: EU27 | B13: Services | D13: M€ | E13: M€/M€ | F13: M€/M€ | G13: M€/M€ | H13: M€/M€ | I13: M€/M€ | J13: M€/M€ | L13: M€ | M13: M€ | O13: M€ | Q13: M€
A14: RoW | B14: Primary | D14: M€ | E14: M€/M€ | F14: M€/M€ | G14: M€/M€ | H14: M€/M€ | I14: M€/M€ | J14: M€/M€ | L14: M€ | M14: M€ | O14: M€ | Q14: M€
A15: RoW | B15: Industry | D15: M€ | E15: M€/M€ | F15: M€/M€ | G15: M€/M€ | H15: M€/M€ | I15: M€/M€ | J15: M€/M€ | L15: M€ | M15: M€ | O15: M€ | Q15: M€
A16: RoW | B16: Services | D16: M€ | E16: M€/M€ | F16: M€/M€ | G16: M€/M€ | H16: M€/M€ | I16: M€/M€ | J16: M€/M€ | L16: M€ | M16: M€ | O16: M€ | Q16: M€
E17: r (2,6) | Q17: Rtot (2,1) = R + R_Y
C18: Value added | D18: M€ | E18: M€/M€ | F18: M€/M€ | G18: M€/M€ | H18: M€/M€ | I18: M€/M€ | J18: M€/M€ | Q18: M€
C19: CO2 emissions | D19: ton | E19: M€/M€ | F19: M€/M€ | G19: M€/M€ | H19: M€/M€ | I19: M€/M€ | J19: M€/M€ | Q19: ton
E20: Z (6,6) = z diag(X) | S20: w (6,6) = inv(I-z)
A21: EU27 | B21: Primary | D21: M€ | E21: M€/M€ | F21: M€/M€ | G21: M€/M€ | H21: M€/M€ | I21: M€/M€ | J21: M€/M€ | S21: M€/M€ | T21: M€/M€ | U21: M€/M€ | V21: M€/M€ | W21: M€/M€ | X21: M€/M€
A22: EU27 | B22: Industry | D22: M€ | E22: M€/M€ | F22: M€/M€ | G22: M€/M€ | H22: M€/M€ | I22: M€/M€ | J22: M€/M€ | S22: M€/M€ | T22: M€/M€ | U22: M€/M€ | V22: M€/M€ | W22: M€/M€ | X22: M€/M€
A23: EU27 | B23: Services | D23: M€ | E23: M€/M€ | F23: M€/M€ | G23: M€/M€ | H23: M€/M€ | I23: M€/M€ | J23: M€/M€ | S23: M€/M€ | T23: M€/M€ | U23: M€/M€ | V23: M€/M€ | W23: M€/M€ | X23: M€/M€
A24: RoW | B24: Primary | D24: M€ | E24: M€/M€ | F24: M€/M€ | G24: M€/M€ | H24: M€/M€ | I24: M€/M€ | J24: M€/M€ | S24: M€/M€ | T24: M€/M€ | U24: M€/M€ | V24: M€/M€ | W24: M€/M€ | X24: M€/M€
A25: RoW | B25: Industry | D25: M€ | E25: M€/M€ | F25: M€/M€ | G25: M€/M€ | H25: M€/M€ | I25: M€/M€ | J25: M€/M€ | S25: M€/M€ | T25: M€/M€ | U25: M€/M€ | V25: M€/M€ | W25: M€/M€ | X25: M€/M€
A26: RoW | B26: Services | D26: M€ | E26: M€/M€ | F26: M€/M€ | G26: M€/M€ | H26: M€/M€ | I26: M€/M€ | J26: M€/M€ | S26: M€/M€ | T26: M€/M€ | U26: M€/M€ | V26: M€/M€ | W26: M€/M€ | X26: M€/M€
E27: R(2,6) = r diag(X) | L27: R_Y (2,2)
C28: Value added | D28: M€ | E28: M€/M€ | F28: M€/M€ | G28: M€/M€ | H28: M€/M€ | I28: M€/M€ | J28: M€/M€ | L28: M€ | M28: M€
C29: CO2 emissions | D29: ton | E29: ton/M€ | F29: ton/M€ | G29: ton/M€ | H29: ton/M€ | I29: ton/M€ | J29: ton/M€ | L29: ton | M29: ton
A32: Numeric solution
E34: z | L34: Y | O34: Y_tot (6,1) = sum(Y) | Q34: X
A35: EU27 | B35: Primary | D35: M€ | E35: {='Ex. 2'!E54:G56+'Ex. 2'!E57:G59} -> 0 | F35: 0 | G35: 0 | H35: 0.00036254252 | I35: 0.00076232406 | J35: 0.00011372549 | L35: {='Ex. 2'!L44:L46+'Ex. 2'!L47:L49} -> 313638.25 | M35: 19713.979 | O35: =SUM(L35:M35) -> 333352.23 | Q35: {=MMULT(MINVERSE(_xlfn.MUNIT(6)-E35:J40),O35:O40)} -> 381197.07
A36: EU27 | B36: Industry | D36: M€ | E36: 0 | F36: 0 | G36: 0 | H36: 0.0046330201 | I36: 0.013447256 | J36: 0.0033946432 | L36: 5286212.3 | M36: 986934.45 | O36: =SUM(L36:M36) -> 6273146.8 | Q36: 7192006
A37: EU27 | B37: Services | D37: M€ | E37: 0 | F37: 0 | G37: 0 | H37: 0.0026523377 | I37: 0.0024673391 | J37: 0.0042358103 | L37: 10400762 | M37: 318899.37 | O37: =SUM(L37:M37) -> 10719661 | Q37: 11130980
A38: RoW | B38: Primary | D38: M€ | E38: 0 | F38: 0 | G38: 0 | H38: 0.092967405 | I38: 0.086503223 | J38: 0.0084539556 | L38: 0 | M38: 1960204.5 | O38: =SUM(L38:M38) -> 1960204.5 | Q38: 7495407.9
A39: RoW | B39: Industry | D39: M€ | E39: 0 | F39: 0 | G39: 0 | H39: 0.12410909 | I39: 0.42327782 | J39: 0.094791331 | L39: 0 | M39: 21737840 | O39: =SUM(L39:M39) -> 21737840 | Q39: 49732629
A40: RoW | B40: Services | D40: M€ | E40: 0 | F40: 0 | G40: 0 | H40: 0.16386307 | I40: 0.16842669 | J40: 0.26404004 | L40: 0 | M40: 37086792 | O40: =SUM(L40:M40) -> 37086792 | Q40: 63442738
E41: r | L41: R_Y | Q41: Rtot
C42: Value added | D42: M€ | E42: 0.518594 | F42: 0.35713987 | G42: 0.6311637 | H42: 0.61141254 | I42: 0.30511534 | J42: 0.62497049 | L42: 0 | M42: 0 | Q42: =SUM(E42:J42,L42:M42) -> 3.0483959
C43: CO2 emissions | D43: ton | E43: 0.23397702 | F43: 0.14662019 | G43: 0.043624128 | H43: 0.34289078 | I43: 0.37917803 | J43: 0.049379483 | L43: 704556.98 | M43: 3735401.4 | Q43: =SUM(E43:J43,L43:M43) -> 4439959.6
E44: Z | S44: w
A45: EU27 | B45: Primary | D45: M€ | E45: {=MMULT(E35:J40,_xlfn.MUNIT(6)*Q35:Q40)} -> 0 | F45: 0 | G45: 0 | H45: 2717.4041 | I45: 37912.38 | J45: 7215.0567 | S45: {=MINVERSE(_xlfn.MUNIT(6)-E35:J40)} -> 1 | T45: 0 | U45: 0 | V45: 0.00067360004 | W45: 0.0015277084 | X45: 0.00035903256
A46: EU27 | B46: Industry | D46: M€ | E46: 0 | F46: 0 | G46: 0 | H46: 34726.376 | I46: 668767.41 | J46: 215365.46 | S46: 0 | T46: 1 | U46: 0 | V46: 0.010329072 | W46: 0.027273558 | X46: 0.0082440105
...
