Workbook

Sheet Ex. 1
A1: products | E1: fuel A | F1: fuel B | G1: heat | H1: electricity | I1: product A | J1: product B
B2: technologies | L2: refinery | M2: gas boiler | N2: chp plant | O2: pv plant | P2: industries
C3: environmental transactions
D4: unit | E4: MWh | F4: MWh | G4: MWh | H4: MWh | I4: ton | J4: ton | L4: MWh | M4: MWh | N4: MWh | O4: MWh | P4: ton
A6: a) Draw the reference production system (RPS)
A19: b) Build the related Supply-Use Table (SUT)
L20: U | R20: Y | T20: Q = sum(U,Y)
A21: fuel A | D21: MWh
A22: fuel B | D22: MWh
A23: heat | D23: MWh
A24: electricity | D24: MWh
A25: product A | D25: ton
A26: product B | D26: ton
E27: S | T27: X = sum(S)
B28: refinery | D28: MWh
B29: gas boiler | D29: MWh
B30: chp plant | D30: MWh
B31: pv plant | D31: MWh
B32: industries | D32: ton
E33: Q'
E34: =SUM(E28:E32) -> 0 | F34: =SUM(F28:F32) -> 0 | G34: =SUM(G28:G32) -> 0 | H34: =SUM(H28:H32) -> 0 | I34: =SUM(I28:I32) -> 0 | J34: =SUM(J28:J32) -> 0
A36: c) Calculate the market share and product mix matrices. Comment on the results: what do these two matrices mean?
L38: u=U*inv(diag(X)) | V38: c=S'*inv(diag(X))
A39: fuel A | D39: MWh | V39: {=MMULT(TRANSPOSE(E28:J32),MINVERSE(_xlfn.MUNIT(5)*T28:T32))} -> #NUM! | W39: #NUM! | X39: #NUM! | Y39: #NUM! | Z39: #NUM!
A40: fuel B | D40: MWh | V40: #NUM! | W40: #NUM! | X40: #NUM! | Y40: #NUM! | Z40: #NUM!
A41: heat | D41: MWh | V41: #NUM! | W41: #NUM! | X41: #NUM! | Y41: #NUM! | Z41: #NUM!
A42: electricity | D42: MWh | V42: #NUM! | W42: #NUM! | X42: #NUM! | Y42: #NUM! | Z42: #NUM!
A43: product A | D43: ton | V43: #NUM! | W43: #NUM! | X43: #NUM! | Y43: #NUM! | Z43: #NUM!
A44: product B | D44: ton | V44: #NUM! | W44: #NUM! | X44: #NUM! | Y44: #NUM! | Z44: #NUM!
E45: d=S*inv(diag(Q)
B46: oil refinery | D46: MWh | E46: {=MMULT(E28:J32,MINVERSE(_xlfn.MUNIT(6)*T21:T26))} -> #NUM! | F46: #NUM! | G46: #NUM! | H46: #NUM! | I46: #NUM! | J46: #NUM!
B47: boiler | D47: MWh | E47: #NUM! | F47: #NUM! | G47: #NUM! | H47: #NUM! | I47: #NUM! | J47: #NUM!
B48: chp plant | D48: MWh | E48: #NUM! | F48: #NUM! | G48: #NUM! | H48: #NUM! | I48: #NUM! | J48: #NUM!
B49: pv plant | D49: MWh | E49: #NUM! | F49: #NUM! | G49: #NUM! | H49: #NUM! | I49: #NUM! | J49: #NUM!
B50: industry | D50: ton | E50: #NUM! | F50: #NUM! | G50: #NUM! | H50: #NUM! | I50: #NUM! | J50: #NUM!
A52: d) Calculate the Leontief Inverse matrix (or matrices?)
A54: Suggested reading: Lenzen and Rueda Cantuce, 2012. https://core.ac.uk/download/pdf/13324962.pdf
A56: N.B. This decomposition of the Leontief inverse matrix goes beyond the scope of the course (only wcc is required), but it may be useful for your projects.
A58: industry-based technology assumption | T58: IOT approach: you can treat a SUT with the same math as a IOT
E59: fuel A | F59: fuel B | G59: heat | H59: electricity | I59: product A | J59: product B | V59: fuel A | W59: fuel B | X59: heat | Y59: electricity | Z59: product A | AA59: product B | AH59: fuel A | AI59: fuel B | AJ59: heat | AK59: electricity | AL59: product A | AM59: product B
...

Sheet Ex. 2
A1: products | E1: aluminium | F1: waste management service | G1: goods | R1: aluminium | S1: waste management service | T1: goods
B2: technologies | I2: aluminium production | J2: waste management | K2: manufacturing | V2: aluminium production | W2: waste management | X2: manufacturing
C3: environmental transactions
D4: units
A5: 1. Define the Reference Production System (RPS) and the Supply and Use Table (SUT) and calculate the total demand by product and total activity by technology.
I6: U | M6: Y | O6: Q = sum(U,Y)
A7: aluminium | D7: kg | O7: =SUM(M7,I7:K7) -> 0
A8: waste management service | D8: kg | O8: =SUM(M8,I8:K8) -> 0
A9: goods | D9: kg | O9: =SUM(M9,I9:K9) -> 0
E10: S | O10: X = sum(V)
B11: aluminium production | D11: kg | O11: =SUM(E11:G11) -> 0
B12: waste management | D12: kg | O12: =SUM(E12:G12) -> 0
B13: manufacturing | D13: kg | O13: =SUM(E13:G13) -> 0
I14: E
C15: electricity | D15: kWh
C16: scraps | D16: kg
A18: 2. Calculate market share and product mix matrices.
I20: u=U*inv(diag(X)) | V20: c=S'*inv(diag(X))
A21: aluminium | D21: kg | I21: {=MMULT(I7:K9,MINVERSE(_xlfn.MUNIT(3)*O11:O13))} -> #NUM! | J21: #NUM! | K21: #NUM! | V21: {=MMULT(TRANSPOSE(E11:G13),MINVERSE(_xlfn.MUNIT(3)*O11:O13))} -> #NUM! | W21: #NUM! | X21: #NUM!
A22: waste management service | D22: kg | I22: #NUM! | J22: #NUM! | K22: #NUM! | V22: #NUM! | W22: #NUM! | X22: #NUM!
A23: goods | D23: kg | I23: #NUM! | J23: #NUM! | K23: #NUM! | V23: #NUM! | W23: #NUM! | X23: #NUM!
E24: d=S*inv(diag(Q) | R24: inv(c)
B25: aluminium production | D25: kg | E25: {=MMULT(E11:G13,MINVERSE(_xlfn.MUNIT(3)*O7:O9))} -> #NUM! | F25: #NUM! | G25: #NUM! | R25: {=MINVERSE(V21:X23)} -> #NUM! | S25: #NUM! | T25: #NUM!
B26: waste management | D26: kg | E26: #NUM! | F26: #NUM! | G26: #NUM! | R26: #NUM! | S26: #NUM! | T26: #NUM!
B27: manufacturing | D27: kg | E27: #NUM! | F27: #NUM! | G27: #NUM! | R27: #NUM! | S27: #NUM! | T27: #NUM!
I28: r=E*inv(diag(X))
C29: electricity | D29: kWh | I29: {=MMULT(I15:K16,MINVERSE(_xlfn.MUNIT(3)*O11:O13))} -> #NUM! | J29: #NUM! | K29: #NUM!
C30: scraps | D30: kg | I30: #NUM! | J30: #NUM! | K30: #NUM!
A32: 3. Calculate the electricity embodied within delivered products by using the two assumptions
E34: w_it = inv(I-u d)
A35: aluminium | D35: kg | E35: {=MINVERSE(_xlfn.MUNIT(3)-MMULT(I21:K23,E25:G27))} -> #NUM! | F35: #NUM! | G35: #NUM! | I35: industry-based tech assumption
A36: waste management service | D36: kg | E36: #NUM! | F36: #NUM! | G36: #NUM!
A37: goods | D37: kg | E37: #NUM! | F37: #NUM! | G37: #NUM!
E38: f_it = r d w_it
C39: electricity | D39: kWh | E39: {=MMULT(I29:K30,MMULT(E25:G27,E35:G37))} -> #NUM! | F39: #NUM! | G39: #NUM!
C40: scraps | D40: kg | E40: #NUM! | F40: #NUM! | G40: #NUM!
E42: wca = inv(I-u inv(c))
B43: aluminium production | D43: kg | E43: {=MINVERSE(_xlfn.MUNIT(3)-MMULT(I21:K23,MINVERSE(V21:X23)))} -> #NUM! | F43: #NUM! | G43: #NUM! | I43: product-based tech assumption
B44: waste management | D44: kg | E44: #NUM! | F44: #NUM! | G44: #NUM!
B45: manufacturing | D45: kg | E45: #NUM! | F45: #NUM! | G45: #NUM!
...

Sheet Ex. 3a,b
A1: regions | F1: EU27 | J1: RoW | O1: EU27 | T1: RoW | Y1: EU27 | Z1: RoW | AB1: Tot
B2: products | F2: Goods | G2: Services | H2: Steel | I2: Electricity | J2: Goods | K2: Services | L2: Steel | M2: Electricity
C3: technologies | O3: Services | P3: Other industries | Q3: Traditional steelmaking | R3: Green steelmaking | S3: Electricity | T3: Services | U3: Other industries | V3: Average steelmaking | W3: Electricity | Y3: Final demand | Z3: Final demand | AB3: Final demand
D4: environmental and value added transactions
E5: units | F5: Mton | G5: G€ | H5: Mton | I5: TJ | J5: Mton | K5: G€ | L5: Mton | M5: TJ | O5: - | P5: - | Q5: - | R5: - | S5: - | T5: - | U5: - | V5: - | W5: -
A6: a. Fill the information on green steelmaking industry in EU27
Y7: Y | AB7: Y_tot
A8: EU27 | B8: Goods | E8: Mton | N8: u | O8: 0.0035125779 | P8: 0.27055148 | Q8: 0.15827163 | R8: 0.12 | S8: 4.1115842e-05 | T8: 8.190845e-05 | U8: 0.0033905806 | V8: 0.0039752339 | W8: 3.2484096e-07 | Y8: 835.54778 | Z8: 145.60867 | AB8: =SUM(Y8:Z8) -> 981.15644
B9: Services | E9: G€ | O9: 4.5711092e-06 | P9: 0.00021778395 | Q9: 0.00014460697 | R9: 0.00014460697 | S9: 5.2547112e-09 | T9: 1.4657737e-07 | U9: 2.9643635e-06 | V9: 2.0349832e-06 | W9: 5.9382574e-11 | Y9: 8.1689306 | Z9: 0.47106018 | AB9: =SUM(Y9:Z9) -> 8.6399908
B10: Steel | E10: Mton | O10: 1.1217512e-05 | P10: 0.022327816 | Q10: 0.097684466 | R10: 0.097684466 | S10: 0 | T10: 3.0386983e-06 | U10: 0.0006116707 | V10: 0.0033408952 | W10: 0 | Y10: 1.9817989 | Z10: 0.7772038 | AB10: =SUM(Y10:Z10) -> 2.7590027
B11: Electricity | E11: TJ | O11: 3.0778015 | P11: 483.15056 | Q11: 234.22695 | R11: 300 | S11: 0.038828749 | T11: 0.026646337 | U11: 2.0564664 | V11: 3.005787 | W11: 1.0140309e-06 | Y11: 3454409.3 | Z11: 83583.261 | AB11: =SUM(Y11:Z11) -> 3537992.6
A12: RoW | B12: Goods | E12: Mton | O12: 0.00039488973 | P12: 0.13987705 | Q12: 0.51737764 | R12: 0.4 | S12: 1.2466997e-05 | T12: 0.012049568 | U12: 0.32560213 | V12: 0.54994051 | W12: 6.9815059e-05 | Y12: 585.78789 | Z12: 7478.1973 | AB12: =SUM(Y12:Z12) -> 8063.9851
B13: Services | E13: G€ | O13: 3.1023562e-07 | P13: 1.764837e-05 | Q13: 9.8309999e-06 | R13: 9.8309999e-06 | S13: 4.1399414e-10 | T13: 5.8021191e-06 | U13: 8.7224283e-05 | V13: 6.5546677e-05 | W13: 1.8183214e-09 | Y13: 0.31707359 | Z13: 30.342105 | AB13: =SUM(Y13:Z13) -> 30.659178
B14: Steel | E14: Mton | O14: 6.0084534e-06 | P14: 0.0079615617 | Q14: 0.017867084 | R14: 0.017867084 | S14: 0 | T14: 7.9322198e-05 | U14: 0.018865912 | V14: 0.24692995 | W14: 0 | Y14: 0.605435 | Z14: 38.459047 | AB14: =SUM(Y14:Z14) -> 39.064482
B15: Electricity | E15: TJ | O15: 0.052307961 | P15: 10.312563 | Q15: 3.1295127 | R15: 5 | S15: 7.1287165e-06 | T15: 6.0507067 | U15: 455.66802 | V15: 327.0202 | W15: 0.048434763 | Y15: 50504.88 | Z15: 20969440 | AB15: =SUM(Y15:Z15) -> 21019945
F16: d
A17: EU27 | C17: Services | E17: - | F17: 0.18943246 | G17: 0.93981212 | H17: 0 | I17: 0.091786105 | J17: 0 | K17: 0 | L17: 0 | M17: 0
C18: Other industries | E18: - | F18: 0.81056754 | G18: 0.060187876 | H18: 0 | I18: 0 | J18: 0 | K18: 0 | L18: 0 | M18: 0
C19: Traditional steelmaking | E19: - | F19: 0 | G19: 0 | H19: 1 | I19: 0 | J19: 0 | K19: 0 | L19: 0 | M19: 0
C20: Green steelmaking | E20: - | F20: 0 | G20: 0 | H20: 0 | I20: 0 | J20: 0 | K20: 0 | L20: 0 | M20: 0
C21: Electricity | E21: - | F21: 0 | G21: 0 | H21: 0 | I21: 0.9082139 | J21: 0 | K21: 0 | L21: 0 | M21: 0
A22: RoW | C22: Services | E22: - | F22: 0 | G22: 0 | H22: 0 | I22: 0 | J22: 0.15854983 | K22: 0.94030067 | L22: 0 | M22: 0.034721038
C23: Other industries | E23: - | F23: 0 | G23: 0 | H23: 0 | I23: 0 | J23: 0.81519142 | K23: 0.059699327 | L23: 0 | M23: 0
C24: Average steelmaking | E24: - | F24: 0 | G24: 0 | H24: 0 | I24: 0 | J24: 0.026092893 | K24: 0 | L24: 1 | M24: 0
C25: Electricity | E25: - | F25: 0 | G25: 0 | H25: 0 | I25: 0 | J25: 0.00016586031 | K25: 0 | L25: 0 | M25: 0.96527896
D27: Value added | E27: G€ | N27: r | O27: 9.3327696e-06 | P27: 0.00033615484 | Q27: 0.00013445362 | R27: =Q27*1.5 -> 0.00020168043 | S27: 8.6675066e-09 | T27: 1.2344967e-05 | U27: 0.00017106332 | V27: 0.00010443155 | W27: 6.0114501e-09 | Y27: R_Y
D28: GHG | E28: Mton | O28: 0.0010966822 | P28: 0.16146899 | Q28: 0.75858537 | R28: 0.3 | S28: 7.4601803e-05 | T28: 0.002717605 | U28: 0.24096643 | V28: 0.67546414 | W28: 0.00013706389 | Y28: 796.06386 | Z28: 3424.6899
F30: w_pp = inv(I - ud) | O30: U = u diag(X) | AB30: Q = wY_tot
A31: EU27 | B31: Goods | E31: Mton | F31: {=MINVERSE(_xlfn.MUNIT(8)-MMULT(O8:W15,F17:M25))} -> 1.7701153 | G31: 0.065624163 | H31: 0.56847289 | I31: 0.00093620527 | J31: 0.024394037 | K31: 0.0022774334 | L31: 0.044220487 | M31: 2.4878302e-05 | O31: {=MMULT(O8:W15,_xlfn.MUNIT(9)*AB40:AB48)} -> 2835.7976 | P31: 1266.1653 | Q31: 27.857354 | R31: 0 | S31: 328.00011 | T31: 159.62598 | U31: 143.8517 | V31: 12.654375 | W31: 17.524815 | AB31: {=MMULT(F31:M38,AB8:AB15)} -> 5772.6337 | AC31: 5772.6337
B32: Services | E32: G€ | F32: 0.00076139089 | G32: 1.0000662 | H32: 0.00057624703 | I32: 1.0264386e-06 | J32: 2.6133167e-05 | K32: 2.506435e-06 | L32: 4.4953042e-05 | M32: 2.8770935e-08 | O32: 3.690378 | P32: 1.0192164 | Q32: 0.025452241 | R32: 0 | S32: 0.041919265 | T32: 0.28565498 | U32: 0.12576864 | V32: 0.0064779685 | W32: 0.0032036251 | AB32: 13.838062 | AC32: 13.838062
B33: Steel | E33: Mton | F33: 0.037301677 | G33: 0.0029651668 | H33: 1.1219234 | I33: 2.1550291e-05 | J33: 0.0023792827 | K33: 0.00020385044 | L33: 0.0078353606 | M33: 1.9289484e-06 | O33: 9.0561961 | P33: 104.49289 | Q33: 17.193422 | R33: 0 | S33: 0 | T33: 5.921919 | U33: 25.951269 | V33: 10.635082 | W33: 0 | AB33: 176.00978 | AC33: 176.00978
B34: Electricity | E34: TJ | F34: 1032.8527 | G34: 85.805811 | H34: 717.67166 | I34: 2.0132995 | J34: 22.580098 | K34: 2.0814855 | L34: 42.679587 | M34: 0.021918067 | O34: 2484791 | P34: 2261116.8 | Q34: 41226.234 | R34: 0 | S34: 309754.92 | T34: 51929.292 | U34: 87249.416 | V34: 9568.3314 | W34: 54.705863 | AB34: 8783683.2 | AC34: 8783683.2
A35: RoW | B35: Goods | E35: Mton | F35: 0.66237457 | G35: 0.053749766 | H35: 1.595965 | I35: 0.00052136731 | J35: 2.2560856 | K35: 0.12142137 | L35: 2.305917 | M35: 0.0014869538 | O35: 318.80498 | P35: 654.61653 | Q35: 91.063525 | R35: 0 | S35: 99.455012 | T35: 23482.609 | U35: 13814.277 | V35: 1750.6274 | W35: 3766.4462 | AB35: 52041.884 | AC35: 52041.884
B36: Services | E36: G€ | F36: 0.00018467347 | G36: 1.5279145e-05 | H36: 0.00033966378 | I36: 1.7337601e-07 | J36: 0.00041333706 | K36: 1.0000422 | L36: 0.00062960179 | M36: 5.4701193e-07 | O36: 0.25046147 | P36: 0.082593353 | Q36: 0.0017303521 | R36: 0 | S36: 0.003302623 | T36: 11.307368 | U36: 3.7006527 | V36: 0.20865495 | W36: 0.098096453 | AB36: 46.312038 | AC36: 46.312038
B37: Steel | E37: Mton | F37: 0.037419005 | G37: 0.0030116767 | H37: 0.081472525 | I37: 2.6233854e-05 | J37: 0.070041106 | K37: 0.0055397239 | L37: 1.4019364 | M37: 5.1182522e-05 | O37: 4.8507842 | P37: 37.25965 | Q37: 3.1447815 | R37: 0 | S37: 0 | T37: 154.58581 | U37: 800.42147 | V37: 786.05291 | W37: 0 | AB37: 1825.3799 | AC37: 1825.3799
B38: Electricity | E38: TJ | F38: 382.78494 | G38: 31.086433 | H38: 869.73816 | I38: 0.30246692 | J38: 1187.7547 | K38: 108.98135 | L38: 1799.7718 | M38: 2.1308043 | O38: 42229.608 | P38: 48262.202 | Q38: 550.82485 | R38: 0 | S38: 56.869073 | T38: 11791824 | U38: 19332564 | V38: 1041004.5 | W38: 2613002.6 | AB38: 55889440 | AC38: 55889440
F39: V = d diag(Q) | AB39: X = dQ | AC39: 807326.6
A40: EU27 | C40: Services | E40: - | F40: {=MMULT(F17:M25,_xlfn.MUNIT(8)*AB31:AB38)} -> 1093.5242 | G40: 13.005178 | H40: 0 | I40: 806220.07 | J40: 0 | K40: 0 | L40: 0 | M40: 0 | AB40: {=MMULT(F17:M25,AB31:AB38)} -> 807326.6 | AC40: 4679.9424
C41: Other industries | E41: - | F41: 4679.1095 | G41: 0.83288355 | H41: 0 | I41: 0 | J41: 0 | K41: 0 | L41: 0 | M41: 0 | AB41: 4679.9424 | AC41: 176.00978
C42: Traditional steelmaking | E42: - | F42: 0 | G42: 0 | H42: 176.00978 | I42: 0 | J42: 0 | K42: 0 | L42: 0 | M42: 0 | AB42: 176.00978 | AC42: 0
...

Sheet Ex. 3c
A1: regions | F1: EU27 | J1: RoW | O1: EU27 | S1: RoW | Y1: EU27 | Z1: RoW | AD1: EU27 | AF1: EU27
B2: products | F2: Goods | G2: Services | H2: Steel | I2: Electricity | J2: Goods | K2: Services | L2: Steel | M2: Electricity
C3: technologies | O3: Services | P3: Other industries | Q3: Traditional steelmaking | R3: Green steelmaking | S3: Electricity | T3: Services | U3: Other industries | V3: Average steelmaking | W3: Electricity | Y3: Final demand | Z3: Final demand
D4: environmental and value added transactions
E5: units | F5: Mton | G5: G€ | H5: Mton | I5: TJ | J5: Mton | K5: G€ | L5: Mton | M5: TJ | O5: - | P5: - | Q5: - | R5: - | S5: - | T5: - | U5: - | V5: -
A6: d. Assess impact of 40% green steel production. Consider this implies 2 Mton of goods, 3 TJ of electricity, 0.5 G€ of services and 0.1 Mton of steel of extra final demand as investment | X6: Y_new = Y(a,b,c) + investments
AB7: Y_tot | AD7: investments | AF7: Y (a,b,c)
A8: EU27 | B8: Goods | E8: Mton | N8: u | O8: {='Ex. 3a,b'!O8:W15} -> 0.0035125779 | P8: 0.27055148 | Q8: 0.15827163 | R8: 0.12 | S8: 4.1115842e-05 | T8: 8.190845e-05 | U8: 0.0033905806 | V8: 0.0039752339 | W8: 3.2484096e-07 | Y8: =AF8+AD8 -> 837.54778 | Z8: {='Ex. 3a,b'!Z8:Z15} -> 145.60867 | AB8: =SUM(Y8:Z8) -> 983.15644 | AD8: 2 | AF8: {='Ex. 3a,b'!Y8:Y15} -> 835.54778
B9: Services | E9: G€ | O9: 4.5711092e-06 | P9: 0.00021778395 | Q9: 0.00014460697 | R9: 0.00014460697 | S9: 5.2547112e-09 | T9: 1.4657737e-07 | U9: 2.9643635e-06 | V9: 2.0349832e-06 | W9: 5.9382574e-11 | Y9: =AF9+AD9 -> 8.6689306 | Z9: 0.47106018 | AB9: =SUM(Y9:Z9) -> 9.1399908 | AD9: 0.5 | AF9: 8.1689306
B10: Steel | E10: Mton | O10: 1.1217512e-05 | P10: 0.022327816 | Q10: 0.097684466 | R10: 0.097684466 | S10: 0 | T10: 3.0386983e-06 | U10: 0.0006116707 | V10: 0.0033408952 | W10: 0 | Y10: =AF10+AD10 -> 2.0817989 | Z10: 0.7772038 | AB10: =SUM(Y10:Z10) -> 2.8590027 | AD10: 0.1 | AF10: 1.9817989
B11: Electricity | E11: TJ | O11: 3.0778015 | P11: 483.15056 | Q11: 234.22695 | R11: 300 | S11: 0.038828749 | T11: 0.026646337 | U11: 2.0564664 | V11: 3.005787 | W11: 1.0140309e-06 | Y11: =AF11+AD11 -> 3454412.3 | Z11: 83583.261 | AB11: =SUM(Y11:Z11) -> 3537995.6 | AD11: 3 | AF11: 3454409.3
A12: RoW | B12: Goods | E12: Mton | O12: 0.00039488973 | P12: 0.13987705 | Q12: 0.51737764 | R12: 0.4 | S12: 1.2466997e-05 | T12: 0.012049568 | U12: 0.32560213 | V12: 0.54994051 | W12: 6.9815059e-05 | Y12: =AF12 -> 585.78789 | Z12: 7478.1973 | AB12: =SUM(Y12:Z12) -> 8063.9851 | AF12: 585.78789
B13: Services | E13: G€ | O13: 3.1023562e-07 | P13: 1.764837e-05 | Q13: 9.8309999e-06 | R13: 9.8309999e-06 | S13: 4.1399414e-10 | T13: 5.8021191e-06 | U13: 8.7224283e-05 | V13: 6.5546677e-05 | W13: 1.8183214e-09 | Y13: =AF13 -> 0.31707359 | Z13: 30.342105 | AB13: =SUM(Y13:Z13) -> 30.659178 | AF13: 0.31707359
B14: Steel | E14: Mton | O14: 6.0084534e-06 | P14: 0.0079615617 | Q14: 0.017867084 | R14: 0.017867084 | S14: 0 | T14: 7.9322198e-05 | U14: 0.018865912 | V14: 0.24692995 | W14: 0 | Y14: =AF14 -> 0.605435 | Z14: 38.459047 | AB14: =SUM(Y14:Z14) -> 39.064482 | AF14: 0.605435
B15: Electricity | E15: TJ | O15: 0.052307961 | P15: 10.312563 | Q15: 3.1295127 | R15: 5 | S15: 7.1287165e-06 | T15: 6.0507067 | U15: 455.66802 | V15: 327.0202 | W15: 0.048434763 | Y15: =AF15 -> 50504.88 | Z15: 20969440 | AB15: =SUM(Y15:Z15) -> 21019945 | AF15: 50504.88
F16: d_new
A17: EU27 | C17: Services | E17: - | F17: ='Ex. 3a,b'!F17 -> 0.18943246 | G17: ='Ex. 3a,b'!G17 -> 0.93981212 | H17: ='Ex. 3a,b'!H17 -> 0 | I17: ='Ex. 3a,b'!I17 -> 0.091786105 | J17: ='Ex. 3a,b'!J17 -> 0 | K17: ='Ex. 3a,b'!K17 -> 0 | L17: ='Ex. 3a,b'!L17 -> 0 | M17: ='Ex. 3a,b'!M17 -> 0
C18: Other industries | E18: - | F18: ='Ex. 3a,b'!F18 -> 0.81056754 | G18: ='Ex. 3a,b'!G18 -> 0.060187876 | H18: ='Ex. 3a,b'!H18 -> 0 | I18: ='Ex. 3a,b'!I18 -> 0 | J18: ='Ex. 3a,b'!J18 -> 0 | K18: ='Ex. 3a,b'!K18 -> 0 | L18: ='Ex. 3a,b'!L18 -> 0 | M18: ='Ex. 3a,b'!M18 -> 0
C19: Traditional steelmaking | E19: - | F19: ='Ex. 3a,b'!F19 -> 0 | G19: ='Ex. 3a,b'!G19 -> 0 | H19: =1-H20 -> 0.6 | I19: ='Ex. 3a,b'!I19 -> 0 | J19: ='Ex. 3a,b'!J19 -> 0 | K19: ='Ex. 3a,b'!K19 -> 0 | L19: ='Ex. 3a,b'!L19 -> 0 | M19: ='Ex. 3a,b'!M19 -> 0
C20: Green steelmaking | E20: - | F20: ='Ex. 3a,b'!F20 -> 0 | G20: ='Ex. 3a,b'!G20 -> 0 | H20: 0.4 | I20: ='Ex. 3a,b'!I20 -> 0 | J20: ='Ex. 3a,b'!J20 -> 0 | K20: ='Ex. 3a,b'!K20 -> 0 | L20: ='Ex. 3a,b'!L20 -> 0 | M20: ='Ex. 3a,b'!M20 -> 0
C21: Electricity | E21: - | F21: ='Ex. 3a,b'!F21 -> 0 | G21: ='Ex. 3a,b'!G21 -> 0 | H21: ='Ex. 3a,b'!H21 -> 0 | I21: ='Ex. 3a,b'!I21 -> 0.9082139 | J21: ='Ex. 3a,b'!J21 -> 0 | K21: ='Ex. 3a,b'!K21 -> 0 | L21: ='Ex. 3a,b'!L21 -> 0 | M21: ='Ex. 3a,b'!M21 -> 0
A22: RoW | C22: Services | E22: - | F22: ='Ex. 3a,b'!F22 -> 0 | G22: ='Ex. 3a,b'!G22 -> 0 | H22: ='Ex. 3a,b'!H22 -> 0 | I22: ='Ex. 3a,b'!I22 -> 0 | J22: ='Ex. 3a,b'!J22 -> 0.15854983 | K22: ='Ex. 3a,b'!K22 -> 0.94030067 | L22: ='Ex. 3a,b'!L22 -> 0 | M22: ='Ex. 3a,b'!M22 -> 0.034721038
C23: Other industries | E23: - | F23: ='Ex. 3a,b'!F23 -> 0 | G23: ='Ex. 3a,b'!G23 -> 0 | H23: ='Ex. 3a,b'!H23 -> 0 | I23: ='Ex. 3a,b'!I23 -> 0 | J23: ='Ex. 3a,b'!J23 -> 0.81519142 | K23: ='Ex. 3a,b'!K23 -> 0.059699327 | L23: ='Ex. 3a,b'!L23 -> 0 | M23: ='Ex. 3a,b'!M23 -> 0
C24: Average steelmaking | E24: - | F24: ='Ex. 3a,b'!F24 -> 0 | G24: ='Ex. 3a,b'!G24 -> 0 | H24: ='Ex. 3a,b'!H24 -> 0 | I24: ='Ex. 3a,b'!I24 -> 0 | J24: ='Ex. 3a,b'!J24 -> 0.026092893 | K24: ='Ex. 3a,b'!K24 -> 0 | L24: ='Ex. 3a,b'!L24 -> 1 | M24: ='Ex. 3a,b'!M24 -> 0
C25: Electricity | E25: - | F25: ='Ex. 3a,b'!F25 -> 0 | G25: ='Ex. 3a,b'!G25 -> 0 | H25: ='Ex. 3a,b'!H25 -> 0 | I25: ='Ex. 3a,b'!I25 -> 0 | J25: ='Ex. 3a,b'!J25 -> 0.00016586031 | K25: ='Ex. 3a,b'!K25 -> 0 | L25: ='Ex. 3a,b'!L25 -> 0 | M25: ='Ex. 3a,b'!M25 -> 0.96527896
D27: Value added | E27: G€ | N27: v | O27: {='Ex. 3a,b'!O27:W28} -> 9.3327696e-06 | P27: 0.00033615484 | Q27: 0.00013445362 | R27: 0.00020168043 | S27: 8.6675066e-09 | T27: 1.2344967e-05 | U27: 0.00017106332 | V27: 0.00010443155 | W27: 6.0114501e-09 | Y27: R_Y
D28: GHG | E28: Mton | N28: r | O28: 0.0010966822 | P28: 0.16146899 | Q28: 0.75858537 | R28: 0.3 | S28: 7.4601803e-05 | T28: 0.002717605 | U28: 0.24096643 | V28: 0.67546414 | W28: 0.00013706389 | Y28: {='Ex. 3a,b'!Y28:Z28} -> 796.06386 | Z28: 3424.6899
F30: w_pp = inv(I - ud) | O30: U = u diag(X) | AB30: Q = wY_tot
A31: EU27 | B31: Goods | E31: Mton | F31: {=MINVERSE(_xlfn.MUNIT(8)-MMULT(O8:W15,F17:M25))} -> 1.7699813 | G31: 0.065613508 | H31: 0.56444121 | I31: 0.00093612782 | J31: 0.024385487 | K31: 0.0022767009 | L31: 0.04419233 | M31: 2.4871371e-05 | O31: {=MMULT(O8:W15,_xlfn.MUNIT(9)*AB40:AB48)} -> 2838.5574 | P31: 1266.8313 | Q31: 16.730385 | R31: 8.4565431 | S31: 328.31934 | T31: 159.60215 | U31: 143.80658 | V31: 12.650824 | W31: 17.522211 | AB31: {=MMULT(F31:M38,AB8:AB15)} -> 5775.6332
B32: Services | E32: G€ | F32: 0.00076191841 | G32: 1.0000662 | H32: 0.00059211311 | I32: 1.0267433e-06 | J32: 2.6166814e-05 | K32: 2.5093178e-06 | L32: 4.5063849e-05 | M32: 2.8798214e-08 | O32: 3.6939695 | P32: 1.0197525 | Q32: 0.015285938 | R32: 0.010190625 | S32: 0.041960063 | T32: 0.28561234 | U32: 0.1257292 | V32: 0.0064761507 | W32: 0.003203149 | AB32: 14.34217
B33: Steel | E33: Mton | F33: 0.037297412 | G33: 0.0029648279 | H33: 1.1217951 | I33: 2.1547827e-05 | J33: 0.0023790107 | K33: 0.00020382713 | L33: 0.0078344649 | M33: 1.9287279e-06 | O33: 9.0650096 | P33: 104.54785 | Q33: 10.325911 | R33: 6.8839408 | S33: 0 | T33: 5.9210349 | U33: 25.94313 | V33: 10.632098 | W33: 0 | AB33: 176.17798
B34: Electricity | E34: TJ | F34: 1034.1997 | G34: 85.91288 | H34: 758.18305 | I34: 2.0140776 | J34: 22.666011 | K34: 2.0888463 | L34: 42.962513 | M34: 0.021987719 | O34: 2487209.2 | P34: 2262306.1 | Q34: 24759.379 | R34: 21141.358 | S34: 310056.39 | T34: 51921.539 | U34: 87222.052 | V34: 9565.6464 | W34: 54.697734 | AB34: 8792232
A35: RoW | B35: Goods | E35: Mton | F35: 0.65859871 | G35: 0.053449618 | H35: 1.4823985 | I35: 0.00051918588 | J35: 2.2558447 | K35: 0.12140074 | L35: 2.3051239 | M35: 0.0014867586 | O35: 319.11525 | P35: 654.96086 | Q35: 54.690329 | R35: 28.188477 | S35: 99.551807 | T35: 23479.103 | U35: 13809.944 | V35: 1750.1362 | W35: 3765.8865 | AB35: 52025.562
B36: Services | E36: G€ | F36: 0.0001840296 | G36: 1.5227963e-05 | H36: 0.00032029817 | I36: 1.7300403e-07 | J36: 0.00041329599 | K36: 1.0000422 | L36: 0.00062946655 | M36: 5.4697863e-07 | O36: 0.25070522 | P36: 0.082636798 | Q36: 0.0010392034 | R36: 0.00069280229 | S36: 0.0033058373 | T36: 11.30568 | U36: 3.699492 | V36: 0.20859639 | W36: 0.098081876 | AB36: 46.309408
B37: Steel | E37: Mton | F37: 0.037302158 | G37: 0.0030023883 | H37: 0.077958108 | I37: 2.6166348e-05 | J37: 0.070033652 | K37: 0.0055390854 | L37: 1.4019119 | M37: 5.117648e-05 | O37: 4.855505 | P37: 37.279249 | Q37: 1.888672 | R37: 1.2591147 | S37: 0 | T37: 154.56273 | U37: 800.17043 | V37: 785.83233 | W37: 0 | AB37: 1824.9125
B38: Electricity | E38: TJ | F38: 380.84271 | G38: 30.932041 | H38: 811.32143 | I38: 0.30134484 | J38: 1187.6308 | K38: 108.97074 | L38: 1799.3638 | M38: 2.1307038 | O38: 42270.706 | P38: 48287.588 | Q38: 330.81074 | R38: 352.35596 | S38: 56.924421 | T38: 11790063 | U38: 19326501 | V38: 1040712.3 | W38: 2612614.3 | AB38: 55881134
F39: V = d diag(Q) | O39: w_tt = inv(I-du) | AB39: X = dQ
A40: EU27 | C40: Services | E40: - | F40: {=MMULT(F17:M25,_xlfn.MUNIT(8)*AB31:AB38)} -> 1094.0924 | G40: 13.478946 | H40: 0 | I40: 807004.72 | J40: 0 | K40: 0 | L40: 0 | M40: 0 | O40: {=MINVERSE(_xlfn.MUNIT(9)-MMULT(F17:M25,O8:W15))} -> 1.905912 | P40: 117.07861 | Q40: 66.384524 | R40: 74.668586 | S40: 0.011127773 | T40: 0.050625255 | U40: 2.42143 | V40: 3.9517756 | W40: 0.0002746814 | AB40: {=MMULT(F17:M25,AB31:AB38)} -> 808112.29
C41: Other industries | E41: - | F41: 4681.5408 | G41: 0.86322476 | H41: 0 | I41: 0 | J41: 0 | K41: 0 | L41: 0 | M41: 0 | O41: 0.0073899567 | P41: 1.7683108 | Q41: 0.46046532 | R41: 0.45318542 | S41: 8.8702984e-05 | T41: 0.00050218101 | U41: 0.023004777 | V41: 0.03582358 | W41: 2.8234458e-06 | AB41: 4682.404
C42: Traditional steelmaking | E42: - | F42: 0 | G42: 0 | H42: 105.70679 | I42: 0 | J42: 0 | K42: 0 | L42: 0 | M42: 0 | O42: 0.00012660887 | P42: 0.02757878 | Q42: 1.0731457 | R42: 0.072974192 | S42: 1.4399269e-06 | T42: 2.8798333e-05 | U42: 0.0015949458 | V42: 0.0047006789 | W42: 1.6298782e-07 | AB42: 105.70679
...

Sheet Ex. 3d
A1: regions | F1: EU27 | J1: RoW | O1: EU27 | S1: RoW | Y1: EU27 | Z1: RoW
B2: products | F2: Goods | G2: Services | H2: Steel | I2: Electricity | J2: Goods | K2: Services | L2: Steel | M2: Electricity
C3: technologies | O3: Services | P3: Other industries | Q3: Traditional steelmaking | R3: Green steelmaking | S3: Electricity | T3: Services | U3: Other industries | V3: Average steelmaking | W3: Electricity | Y3: Final demand | Z3: Final demand
D4: environmental and value added transactions
E5: units | F5: Mton | G5: G€ | H5: Mton | I5: TJ | J5: Mton | K5: G€ | L5: Mton | M5: TJ | O5: - | P5: - | Q5: - | R5: - | S5: - | T5: - | U5: - | V5: -
A6: e. (EXTRA) Compare results of point d with the case in which EU fully offshores steel production to RoW
Y7: Y_new | AB7: Y_tot
A8: EU27 | B8: Goods | E8: Mton | N8: u_new | O8: {='Ex. 3a,b'!O8:W9} -> 0.0035125779 | P8: 0.27055148 | Q8: 0.15827163 | R8: 0.12 | S8: 4.1115842e-05 | T8: 8.190845e-05 | U8: 0.0033905806 | V8: 0.0039752339 | W8: 3.2484096e-07 | Y8: {='Ex. 3a,b'!Y8:Z9} -> 835.54778 | Z8: 145.60867 | AB8: =SUM(Y8:Z8) -> 981.15644
B9: Services | E9: G€ | O9: 4.5711092e-06 | P9: 0.00021778395 | Q9: 0.00014460697 | R9: 0.00014460697 | S9: 5.2547112e-09 | T9: 1.4657737e-07 | U9: 2.9643635e-06 | V9: 2.0349832e-06 | W9: 5.9382574e-11 | Y9: 8.1689306 | Z9: 0.47106018 | AB9: =SUM(Y9:Z9) -> 8.6399908
B10: Steel | E10: Mton | O10: 0 | P10: 0 | Q10: 0 | R10: 0 | S10: 0 | T10: 0 | U10: 0 | V10: 0 | W10: 0 | Y10: 0 | Z10: 0 | AB10: =SUM(Y10:Z10) -> 0
B11: Electricity | E11: TJ | O11: {='Ex. 3a,b'!O11:W13} -> 3.0778015 | P11: 483.15056 | Q11: 234.22695 | R11: 300 | S11: 0.038828749 | T11: 0.026646337 | U11: 2.0564664 | V11: 3.005787 | W11: 1.0140309e-06 | Y11: {='Ex. 3a,b'!Y11:Z13} -> 3454409.3 | Z11: 83583.261 | AB11: =SUM(Y11:Z11) -> 3537992.6
A12: RoW | B12: Goods | E12: Mton | O12: 0.00039488973 | P12: 0.13987705 | Q12: 0.51737764 | R12: 0.4 | S12: 1.2466997e-05 | T12: 0.012049568 | U12: 0.32560213 | V12: 0.54994051 | W12: 6.9815059e-05 | Y12: 585.78789 | Z12: 7478.1973 | AB12: =SUM(Y12:Z12) -> 8063.9851
B13: Services | E13: G€ | O13: 3.1023562e-07 | P13: 1.764837e-05 | Q13: 9.8309999e-06 | R13: 9.8309999e-06 | S13: 4.1399414e-10 | T13: 5.8021191e-06 | U13: 8.7224283e-05 | V13: 6.5546677e-05 | W13: 1.8183214e-09 | Y13: 0.31707359 | Z13: 30.342105 | AB13: =SUM(Y13:Z13) -> 30.659178
B14: Steel | E14: Mton | O14: {='Ex. 3a,b'!O10:W10+'Ex. 3a,b'!O14:W14} -> 1.7225966e-05 | P14: 0.030289377 | Q14: 0.11555155 | R14: 0.11555155 | S14: 0 | T14: 8.2360896e-05 | U14: 0.019477583 | V14: 0.25027085 | W14: 0 | Y14: {='Ex. 3a,b'!Y10:Z10+'Ex. 3a,b'!Y14:Z14} -> 2.5872339 | Z14: 39.236251 | AB14: =SUM(Y14:Z14) -> 41.823484
B15: Electricity | E15: TJ | O15: {='Ex. 3a,b'!O15:W15} -> 0.052307961 | P15: 10.312563 | Q15: 3.1295127 | R15: 5 | S15: 7.1287165e-06 | T15: 6.0507067 | U15: 455.66802 | V15: 327.0202 | W15: 0.048434763 | Y15: {='Ex. 3a,b'!Y15:Z15} -> 50504.88 | Z15: 20969440 | AB15: =SUM(Y15:Z15) -> 21019945
F16: d
A17: EU27 | C17: Services | E17: - | F17: {='Ex. 3a,b'!F17:M25} -> 0.18943246 | G17: 0.93981212 | H17: 0 | I17: 0.091786105 | J17: 0 | K17: 0 | L17: 0 | M17: 0
C18: Other industries | E18: - | F18: 0.81056754 | G18: 0.060187876 | H18: 0 | I18: 0 | J18: 0 | K18: 0 | L18: 0 | M18: 0
C19: Traditional steelmaking | E19: - | F19: 0 | G19: 0 | H19: 1 | I19: 0 | J19: 0 | K19: 0 | L19: 0 | M19: 0
C20: Green steelmaking | E20: - | F20: 0 | G20: 0 | H20: 0 | I20: 0 | J20: 0 | K20: 0 | L20: 0 | M20: 0
C21: Electricity | E21: - | F21: 0 | G21: 0 | H21: 0 | I21: 0.9082139 | J21: 0 | K21: 0 | L21: 0 | M21: 0
A22: RoW | C22: Services | E22: - | F22: 0 | G22: 0 | H22: 0 | I22: 0 | J22: 0.15854983 | K22: 0.94030067 | L22: 0 | M22: 0.034721038
C23: Other industries | E23: - | F23: 0 | G23: 0 | H23: 0 | I23: 0 | J23: 0.81519142 | K23: 0.059699327 | L23: 0 | M23: 0
C24: Average steelmaking | E24: - | F24: 0 | G24: 0 | H24: 0 | I24: 0 | J24: 0.026092893 | K24: 0 | L24: 1 | M24: 0
C25: Electricity | E25: - | F25: 0 | G25: 0 | H25: 0 | I25: 0 | J25: 0.00016586031 | K25: 0 | L25: 0 | M25: 0.96527896
D27: Value added | E27: G€ | N27: r | O27: {='Ex. 3a,b'!O27:W28} -> 9.3327696e-06 | P27: 0.00033615484 | Q27: 0.00013445362 | R27: 0.00020168043 | S27: 8.6675066e-09 | T27: 1.2344967e-05 | U27: 0.00017106332 | V27: 0.00010443155 | W27: 6.0114501e-09 | Y27: R_Y
D28: GHG | E28: Mton | O28: 0.0010966822 | P28: 0.16146899 | Q28: 0.75858537 | R28: 0.3 | S28: 7.4601803e-05 | T28: 0.002717605 | U28: 0.24096643 | V28: 0.67546414 | W28: 0.00013706389 | Y28: {='Ex. 3a,b'!Y28:Z28} -> 796.06386 | Z28: 3424.6899
F30: w_pp = inv(I - ud) | O30: U = u diag(X) | AB30: Q = wY_tot
A31: EU27 | B31: Goods | E31: Mton | F31: {=MINVERSE(_xlfn.MUNIT(8)-MMULT(O8:W15,F17:M25))} -> 1.7525624 | G31: 0.064228856 | H31: 0.51109984 | I31: 0.00092606442 | J31: 0.023274426 | K31: 0.0021815082 | L31: 0.040533429 | M31: 2.3970604e-05 | O31: {=MMULT(O8:W15,_xlfn.MUNIT(9)*AB40:AB48)} -> 2801.3612 | P31: 1248.0006 | Q31: 3.9177266e-10 | R31: 0 | S31: 324.018 | T31: 160.04531 | U31: 144.16172 | V31: 13.495299 | W31: 17.570887 | AB31: {=MMULT(F31:M38,AB8:AB15)} -> 5689.8094
B32: Services | E32: G€ | F32: 0.00074360221 | G32: 1.0000648 | H32: 0.00051810336 | I32: 1.0161615e-06 | J32: 2.4998518e-05 | K32: 2.4092214e-06 | L32: 4.1216461e-05 | M32: 2.7851044e-08 | O32: 3.645564 | P32: 1.0045944 | Q32: 3.5794828e-13 | R32: 0 | S32: 0.041410341 | T32: 0.28640538 | U32: 0.12603969 | V32: 0.0069084505 | W32: 0.0032120473 | AB32: 13.754125
B33: Steel | E33: Mton | F33: 3.0423429e-14 | G33: -1.9014643e-15 | H33: 1 | I33: -1.485519e-17 | J33: 0 | K33: 0 | L33: 0 | M33: 1.1884152e-16 | O33: 0 | P33: 0 | Q33: 0 | R33: 0 | S33: 0 | T33: 0 | U33: 0 | V33: 0 | W33: 0 | AB33: 2.4753183e-09
B34: Electricity | E34: TJ | F34: 1010.2528 | G34: 84.009307 | H34: 643.80199 | I34: 2.0002428 | J34: 21.138563 | K34: 1.9579787 | L34: 37.932381 | M34: 0.020749376 | O34: 2454617 | P34: 2228678.2 | Q34: 5.7978627e-07 | R34: 0 | S34: 305994.31 | T34: 52065.707 | U34: 87437.451 | V34: 10204.178 | W34: 54.849683 | AB34: 8677044.3
A35: RoW | B35: Goods | E35: Mton | F35: 0.68614504 | G35: 0.055639317 | H35: 1.6736606 | I35: 0.00053510022 | J35: 2.2576018 | K35: 0.12155128 | L35: 2.3109101 | M35: 0.001488183 | O35: 314.93358 | P35: 645.22522 | Q35: 1.2806743e-09 | R35: 0 | S35: 98.247571 | T35: 23544.296 | U35: 13844.049 | V35: 1866.9623 | W35: 3776.3481 | AB35: 52154.047
B36: Services | E36: G€ | F36: 0.00019438111 | G36: 1.6050821e-05 | H36: 0.00037139397 | I36: 1.789844e-07 | J36: 0.00041395626 | K36: 1.0000423 | L36: 0.00063164092 | M36: 5.4751393e-07 | O36: 0.24741999 | P36: 0.081408447 | Q36: 2.4334854e-14 | R36: 0 | S36: 0.0032625272 | T36: 11.337072 | U36: 3.7086281 | V36: 0.22252074 | W36: 0.098354346 | AB36: 46.357844
B37: Steel | E37: Mton | F37: 0.081630518 | G37: 0.0065261169 | H37: 0.22598125 | I37: 5.1776163e-05 | J37: 0.072861131 | K37: 0.005781336 | L37: 1.4112232 | M37: 5.3468793e-05 | O37: 13.738101 | P37: 139.71892 | Q37: 2.8602687e-10 | R37: 0 | S37: 0 | T37: 160.92937 | U37: 828.1537 | V37: 849.63049 | W37: 0 | AB37: 2033.9941
B38: Electricity | E38: TJ | F38: 413.92415 | G38: 33.561735 | H38: 971.51904 | I38: 0.32045697 | J38: 1189.7409 | K38: 109.15152 | L38: 1806.3127 | M38: 2.1324146 | O38: 41716.794 | P38: 47569.819 | Q38: 7.7465402e-09 | R38: 0 | S38: 56.17865 | T38: 11822800 | U38: 19374229 | V38: 1110182.6 | W38: 2619872.1 | AB38: 56036372
F39: V = d diag(Q) | O39: w_tt = inv(I-du) | AB39: X = dQ
A40: EU27 | C40: Services | E40: - | F40: {=MMULT(F17:M25,_xlfn.MUNIT(8)*AB31:AB38)} -> 1077.8346 | G40: 12.926294 | H40: 0 | I40: 796432.09 | J40: 0 | K40: 0 | L40: 0 | M40: 0 | O40: {=MINVERSE(_xlfn.MUNIT(9)-MMULT(F17:M25,O8:W15))} -> 1.8934578 | P40: 114.36576 | Q40: 59.189382 | R40: 67.490313 | S40: 0.010986131 | T40: 0.047792441 | U40: 2.2645395 | V40: 3.4893825 | W40: 0.00025864873 | AB40: {=MMULT(F17:M25,AB31:AB38)} -> 797522.85
C41: Other industries | E41: - | F41: 4611.9748 | G41: 0.82783158 | H41: 0 | I41: 0 | J41: 0 | K41: 0 | L41: 0 | M41: 0 | O41: 0.0073100695 | P41: 1.7509092 | Q41: 0.41431212 | R41: 0.40714042 | S41: 8.7794424e-05 | T41: 0.00048400994 | U41: 0.021998404 | V41: 0.032857563 | W41: 2.7206043e-06 | AB41: 4612.8026
C42: Traditional steelmaking | E42: - | F42: 0 | G42: 0 | H42: 2.4753183e-09 | I42: 0 | J42: 0 | K42: 0 | L42: 0 | M42: 0 | O42: 0 | P42: 0 | Q42: 1 | R42: -6.2984752e-14 | S42: 0 | T42: 1.9682735e-15 | U42: 2.5193901e-13 | V42: 2.5193901e-13 | W42: 2.4603419e-16 | AB42: 2.4753183e-09
...

Sheet Ex. 3e
A1: regions | F1: EU27 | J1: RoW | O1: EU27 | S1: RoW | Y1: EU27 | Z1: RoW
B2: products | F2: Goods | G2: Services | H2: Steel | I2: Electricity | J2: Goods | K2: Services | L2: Steel | M2: Electricity
C3: technologies | O3: Services | P3: Other industries | Q3: Traditional steelmaking | R3: Green steelmaking | S3: Electricity | T3: Services | U3: Other industries | V3: Average steelmaking | W3: Electricity | Y3: Final demand | Z3: Final demand
D4: environmental and value added transactions
E5: units | F5: Mton | G5: G€ | H5: Mton | I5: TJ | J5: Mton | K5: G€ | L5: Mton | M5: TJ | O5: - | P5: - | Q5: - | R5: - | S5: - | T5: - | U5: - | V5: -
A6: f. What is the optimal market share of EU steel to have a domestic price increase of less than 1%? What would be the GHG footprint in this case?
Y7: Y | AB7: Y_tot
A8: EU27 | B8: Goods | E8: Mton | N8: u | O8: {='Ex. 3a,b'!O8:W15} -> 0.0035125779 | P8: 0.27055148 | Q8: 0.15827163 | R8: 0.12 | S8: 4.1115842e-05 | T8: 8.190845e-05 | U8: 0.0033905806 | V8: 0.0039752339 | W8: 3.2484096e-07 | Y8: {='Ex. 3a,b'!Y8:Z15} -> 835.54778 | Z8: 145.60867 | AB8: =SUM(Y8:Z8) -> 981.15644
B9: Services | E9: G€ | O9: 4.5711092e-06 | P9: 0.00021778395 | Q9: 0.00014460697 | R9: 0.00014460697 | S9: 5.2547112e-09 | T9: 1.4657737e-07 | U9: 2.9643635e-06 | V9: 2.0349832e-06 | W9: 5.9382574e-11 | Y9: 8.1689306 | Z9: 0.47106018 | AB9: =SUM(Y9:Z9) -> 8.6399908
B10: Steel | E10: Mton | O10: 1.1217512e-05 | P10: 0.022327816 | Q10: 0.097684466 | R10: 0.097684466 | S10: 0 | T10: 3.0386983e-06 | U10: 0.0006116707 | V10: 0.0033408952 | W10: 0 | Y10: 1.9817989 | Z10: 0.7772038 | AB10: =SUM(Y10:Z10) -> 2.7590027
B11: Electricity | E11: TJ | O11: 3.0778015 | P11: 483.15056 | Q11: 234.22695 | R11: 300 | S11: 0.038828749 | T11: 0.026646337 | U11: 2.0564664 | V11: 3.005787 | W11: 1.0140309e-06 | Y11: 3454409.3 | Z11: 83583.261 | AB11: =SUM(Y11:Z11) -> 3537992.6
A12: RoW | B12: Goods | E12: Mton | O12: 0.00039488973 | P12: 0.13987705 | Q12: 0.51737764 | R12: 0.4 | S12: 1.2466997e-05 | T12: 0.012049568 | U12: 0.32560213 | V12: 0.54994051 | W12: 6.9815059e-05 | Y12: 585.78789 | Z12: 7478.1973 | AB12: =SUM(Y12:Z12) -> 8063.9851
B13: Services | E13: G€ | O13: 3.1023562e-07 | P13: 1.764837e-05 | Q13: 9.8309999e-06 | R13: 9.8309999e-06 | S13: 4.1399414e-10 | T13: 5.8021191e-06 | U13: 8.7224283e-05 | V13: 6.5546677e-05 | W13: 1.8183214e-09 | Y13: 0.31707359 | Z13: 30.342105 | AB13: =SUM(Y13:Z13) -> 30.659178
B14: Steel | E14: Mton | O14: 6.0084534e-06 | P14: 0.0079615617 | Q14: 0.017867084 | R14: 0.017867084 | S14: 0 | T14: 7.9322198e-05 | U14: 0.018865912 | V14: 0.24692995 | W14: 0 | Y14: 0.605435 | Z14: 38.459047 | AB14: =SUM(Y14:Z14) -> 39.064482
B15: Electricity | E15: TJ | O15: 0.052307961 | P15: 10.312563 | Q15: 3.1295127 | R15: 5 | S15: 7.1287165e-06 | T15: 6.0507067 | U15: 455.66802 | V15: 327.0202 | W15: 0.048434763 | Y15: 50504.88 | Z15: 20969440 | AB15: =SUM(Y15:Z15) -> 21019945
F16: d_new
A17: EU27 | C17: Services | E17: - | F17: {='Ex. 3a,b'!F17:G25} -> 0.18943246 | G17: 0.93981212 | H17: {='Ex. 3a,b'!H17:H18} -> 0 | I17: {='Ex. 3a,b'!I17:M25} -> 0.091786105 | J17: 0 | K17: 0 | L17: 0 | M17: 0
C18: Other industries | E18: - | F18: 0.81056754 | G18: 0.060187876 | H18: 0 | I18: 0 | J18: 0 | K18: 0 | L18: 0 | M18: 0
C19: Traditional steelmaking | E19: - | F19: 0 | G19: 0 | H19: =1-H20 -> 0.71873428 | I19: 0 | J19: 0 | K19: 0 | L19: 0 | M19: 0
C20: Green steelmaking | E20: - | F20: 0 | G20: 0 | H20: 0.28126572 | I20: 0 | J20: 0 | K20: 0 | L20: 0 | M20: 0
C21: Electricity | E21: - | F21: 0 | G21: 0 | H21: {='Ex. 3a,b'!H21:H25} -> 0 | I21: 0.9082139 | J21: 0 | K21: 0 | L21: 0 | M21: 0
A22: RoW | C22: Services | E22: - | F22: 0 | G22: 0 | H22: 0 | I22: 0 | J22: 0.15854983 | K22: 0.94030067 | L22: 0 | M22: 0.034721038
C23: Other industries | E23: - | F23: 0 | G23: 0 | H23: 0 | I23: 0 | J23: 0.81519142 | K23: 0.059699327 | L23: 0 | M23: 0
C24: Average steelmaking | E24: - | F24: 0 | G24: 0 | H24: 0 | I24: 0 | J24: 0.026092893 | K24: 0 | L24: 1 | M24: 0
C25: Electricity | E25: - | F25: 0 | G25: 0 | H25: 0 | I25: 0 | J25: 0.00016586031 | K25: 0 | L25: 0 | M25: 0.96527896
D27: Value added | E27: G€ | N27: r | O27: {='Ex. 3a,b'!O27:W28} -> 9.3327696e-06 | P27: 0.00033615484 | Q27: 0.00013445362 | R27: 0.00020168043 | S27: 8.6675066e-09 | T27: 1.2344967e-05 | U27: 0.00017106332 | V27: 0.00010443155 | W27: 6.0114501e-09 | Y27: R_Y
D28: GHG | E28: Mton | O28: 0.0010966822 | P28: 0.16146899 | Q28: 0.75858537 | R28: 0.3 | S28: 7.4601803e-05 | T28: 0.002717605 | U28: 0.24096643 | V28: 0.67546414 | W28: 0.00013706389 | Y28: {='Ex. 3a,b'!Y28:Z28} -> 796.06386 | Z28: 3424.6899
F30: w_pp = inv(I - ud) | O30: U = u diag(X) | AB30: Q = wY_tot
A31: EU27 | B31: Goods | E31: Mton | F31: {=MINVERSE(_xlfn.MUNIT(8)-MMULT(O8:W15,F17:M25))} -> 1.7700211 | G31: 0.065616671 | H31: 0.56563786 | I31: 0.00093615081 | J31: 0.024388025 | K31: 0.0022769183 | L31: 0.044200687 | M31: 2.4873428e-05 | O31: {=MMULT(O8:W15,_xlfn.MUNIT(9)*AB40:AB48)} -> 2837.2382 | P31: 1266.0678 | Q31: 20.020426 | R31: 5.9401847 | S31: 328.167 | T31: 159.60749 | U31: 143.81707 | V31: 12.651534 | W31: 17.522794 | AB31: {=MMULT(F31:M38,AB8:AB15)} -> 5772.1889
B32: Services | E32: G€ | F32: 0.00076176183 | G32: 1.0000662 | H32: 0.00058740387 | I32: 1.0266529e-06 | J32: 2.6156827e-05 | K32: 2.5084622e-06 | L32: 4.503096e-05 | M32: 2.8790117e-08 | O32: 3.6922527 | P32: 1.0191379 | Q32: 0.018291927 | R32: 0.0071582674 | S32: 0.041940594 | T32: 0.2856219 | U32: 0.12573837 | V32: 0.0064765143 | W32: 0.0032032557 | AB32: 13.839812
B33: Steel | E33: Mton | F33: 0.037298678 | G33: 0.0029649285 | H33: 1.1218332 | I33: 2.1548558e-05 | J33: 0.0023790914 | K33: 0.00020383405 | L33: 0.0078347307 | M33: 1.9287934e-06 | O33: 9.0607966 | P33: 104.48484 | Q33: 12.356508 | R33: 4.8355314 | S33: 0 | T33: 5.9212331 | U33: 25.945022 | V33: 10.632695 | W33: 0 | AB33: 175.99563
B34: Electricity | E34: TJ | F34: 1033.7999 | G34: 85.881101 | H34: 746.15879 | I34: 2.0138466 | J34: 22.640511 | K34: 2.0866615 | L34: 42.878538 | M34: 0.021967046 | O34: 2486053.3 | P34: 2260942.6 | Q34: 29628.326 | R34: 14850.462 | S34: 309912.52 | T34: 51923.277 | U34: 87228.413 | V34: 9566.1835 | W34: 54.699555 | AB34: 8788152.4
A35: RoW | B35: Goods | E35: Mton | F35: 0.65971943 | G35: 0.053538705 | H35: 1.5161064 | I35: 0.00051983336 | J35: 2.2559162 | K35: 0.12140686 | L35: 2.3053593 | M35: 0.0014868165 | O35: 318.96693 | P35: 654.56612 | Q35: 65.445215 | R35: 19.800616 | S35: 99.505615 | T35: 23479.889 | U35: 13810.952 | V35: 1750.2344 | W35: 3766.012 | AB35: 52029.356
B36: Services | E36: G€ | F36: 0.00018422071 | G36: 1.5243155e-05 | H36: 0.00032604611 | I36: 1.7311443e-07 | J36: 0.00041330818 | K36: 1.0000422 | L36: 0.00062950669 | M36: 5.4698852e-07 | O36: 0.2505887 | P36: 0.082586993 | Q36: 0.0012435634 | R36: 0.00048664962 | S36: 0.0033043034 | T36: 11.306058 | U36: 3.6997618 | V36: 0.20860811 | W36: 0.098085142 | AB36: 46.309902
B37: Steel | E37: Mton | F37: 0.03733684 | G37: 0.0030051452 | H37: 0.079001229 | I37: 2.6186384e-05 | J37: 0.070035865 | K37: 0.0055392749 | L37: 1.4019192 | M37: 5.1178273e-05 | O37: 4.8532484 | P37: 37.25678 | Q37: 2.2600805 | R37: 0.88444813 | S37: 0 | T37: 154.5679 | U37: 800.22879 | V37: 785.87645 | W37: 0 | AB37: 1824.9922
B38: Electricity | E38: TJ | F38: 381.41918 | G38: 30.977867 | H38: 828.66021 | I38: 0.30167789 | J38: 1187.6676 | K38: 108.97389 | L38: 1799.4849 | M38: 2.1307337 | O38: 42251.061 | P38: 48258.485 | Q38: 395.86488 | R38: 247.50769 | S38: 56.898008 | T38: 11790458 | U38: 19327910 | V38: 1040770.8 | W38: 2612701.3 | AB38: 55882995
F39: V = d diag(Q) | O39: w_tt = inv(I-du) | AB39: X = dQ
A40: EU27 | C40: Services | E40: - | F40: {=MMULT(F17:M25,_xlfn.MUNIT(8)*AB31:AB38)} -> 1093.44 | G40: 13.006823 | H40: 0 | I40: 806630.27 | J40: 0 | K40: 0 | L40: 0 | M40: 0 | O40: {=MINVERSE(_xlfn.MUNIT(9)-MMULT(F17:M25,O8:W15))} -> 1.9057044 | P40: 117.0334 | Q40: 66.264609 | R40: 74.548953 | S40: 0.011125412 | T40: 0.050578044 | U40: 2.4188153 | V40: 3.9440693 | W40: 0.0002744142 | AB40: {=MMULT(F17:M25,AB31:AB38)} -> 807736.72
C41: Other industries | E41: - | F41: 4678.749 | G41: 0.8329889 | H41: 0 | I41: 0 | J41: 0 | K41: 0 | L41: 0 | M41: 0 | O41: 0.0073901391 | P41: 1.7683505 | Q41: 0.4605707 | R41: 0.45329055 | S41: 8.8705058e-05 | T41: 0.0005022225 | U41: 0.023007075 | V41: 0.035830352 | W41: 2.8236806e-06 | AB41: 4679.582
C42: Traditional steelmaking | E42: - | F42: 0 | G42: 0 | H42: 126.49409 | I42: 0 | J42: 0 | K42: 0 | L42: 0 | M42: 0 | O42: 0.0001516687 | P42: 0.033037478 | Q42: 1.0876235 | R42: 0.087418055 | S42: 1.7249333e-06 | T42: 3.4498419e-05 | U42: 0.0019106352 | V42: 0.0056310895 | W42: 1.9524819e-07 | AB42: 126.49409
...
